Workbook

Sheet Cover
A1: DIAGEO PLC (DGE.L)
A2: Discounted Cash Flow Valuation
A4: Prepared by | B4: NAVEEN THOTA
A5: Date | B5: 46296
A6: Email | B6: nthota0000@gmail.com
A7: LinkedIn
A9: RECOMMENDATION
A10: Rating | B10: BUY on recovery
A11: Target Price (£) | B11: £17.43
A12: Current Price (£) | B12: £16.65
A13: Upside | B13: 0.047
A14: Investment Horizon | B14: 12-18 months
A16: COMPANY OVERVIEW
A17: Sector | B17: Consumer Staples - Spirits
A18: Market Cap | B18: £35.9bn ($45.5bn)
A19: Enterprise Value | B19: $67.4bn
A20: Fiscal Year End | B20: 46203
A21: Headquarters | B21: London, United Kingdom
A22: Shares Outstanding | B22: 2,215m
A24: VALUATION SUMMARY
A25: DCF Target | B25: £19.89
A26: Comps EV/EBITDA Target | B26: £13.46
A27: Comps EV/Revenue Target | B27: £16.47
A28: Blended Target | B28: £17.43
A30: KEY ASSUMPTIONS
A31: WACC | B31: 0.0726
A32: Terminal Growth | B32: 0.0225
A33: Base Year | B33: FY25
A34: Forecast Period | B34: FY26 - FY30
A35: FY30 EBIT Margin | B35: 0.3
A37: NAVIGATION
A38: Historical | B38: 5-year historical P&L (FY21-FY25)
A39: Assumptions | B39: Forecast inputs and WACC calculation
A40: Projections | B40: 5-year forward P&L and FCF forecast
A41: DCF | B41: Enterprise value and target price
A42: Sensitivity | B42: 25 WACC / growth scenarios
A43: Comps | B43: Peer multiple analysis
A45: SOURCES
A46: Annual Reports | B46: Diageo FY21-FY25 (diageo.com/investors)
A47: Share Price | B47: London Stock Exchange, 20 October 2026
...

Sheet Assumptions
A1: DIAGEO PLC - VALUATION ASSUMPTIONS
A3: FORECAST PERIOD
A4: Forecast years | B4: 5
A5: Base year | B5: FY25
A6: First forecast year | B6: FY26
A7: Terminal year | B7: FY30
A9: REVENUE GROWTH ASSUMPTIONS
A10: Revenue growth FY26 | B10: -0.01
A11: Revenue growth FY27 | B11: 0.02
A12: Revenue growth FY28 | B12: 0.04
A13: Revenue growth FY29 | B13: 0.04
A14: Revenue growth FY30 | B14: 0.035
A15: Terminal growth rate | B15: 0.0225
A17: OPERATING ASSUMPTIONS
A18: EBIT margin FY26 | B18: 0.22
A19: EBIT margin FY27 | B19: 0.25
A20: EBIT margin FY28 | B20: 0.275
A21: EBIT margin FY29 | B21: 0.29
A22: EBIT margin FY30 | B22: 0.295
A24: CASH FLOW ASSUMPTION
A25: Effective Tax Rate | B25: 0.23
A26: D&A % of revenue | B26: 0.045
A27: Capex % of revenue | B27: 0.07
A28: Change in WC % of revenue | B28: 0.01
A30: WACC INPUTS
A31: Risk-free rate (10Y UK Gilt) | B31: 0.045
A32: Equity Risk premium | B32: 0.055
A33: Beta | B33: 0.8
A34: Cost of equity | B34: =B31+B32*B33 -> 0.089
A35: Pre-tax cost of debt | B35: 0.05
A36: Tax rate for debt shield | B36: 0.23
A37: After-tax cost of debt | B37: =B35*(1-B36) -> 0.0385
A38: Market value of equity ($m) | B38: 45472.953
A39: Net debt ($m) | B39: 21900
A40: Total capital ($m) | B40: =B38+B39 -> 67372.953
A41: Weight of equity | B41: =B38/B40 -> 0.67494374
A42: Weight of debt | B42: =B39/B40 -> 0.32505626
A43: WACC | B43: =B41*B34+B42*B37 -> 0.072584659
A45: SHARE DATA
A46: Current share price (£) | B46: 16.165
...

Sheet Historical
A1: DIAGEO PLC - HISTORICAL P&L ($ millions) | B1: FY21 | C1: FY22 | D1: FY23 | E1: FY24 | F1: FY25
A3: NET SALES | B3: 12733 | C3: 15452 | D3: 20555 | E3: 20269 | F3: 20245
A4: Cost of sales | B4: 5038 | C4: 5973 | D4: 8289 | E4: 8071 | F4: 8072
A5: Gross profit | B5: 7695 | C5: 9479 | D5: 12266 | E5: 12198 | F5: 12173
A6: Gross margin % | B6: =B5/B3 -> 0.60433519 | C6: =C5/C3 -> 0.6134481 | D6: =D5/D3 -> 0.59674045 | E6: =E5/E3 -> 0.60180571 | F6: =F5/F3 -> 0.60128427
A8: Marketing | B8: 2163 | C8: 2721 | D8: 3663 | E8: 3691 | F8: 3662
A9: Other operating expenses | B9: 1801 | C9: 2349 | D9: 3056 | E9: 2506 | F9: 4176
A10: Operating profit (EBIT) | B10: =B5-B8-B9 -> 3731 | C10: =C5-C8-C9 -> 4409 | D10: =D5-D8-D9 -> 5547 | E10: =E5-E8-E9 -> 6001 | F10: =F5-F8-F9 -> 4335
A11: EBIT margin % | B11: =B10/B3 -> 0.29301814 | C11: =C10/C3 -> 0.28533523 | D11: =D10/D3 -> 0.26986135 | E11: =E10/E3 -> 0.29606789 | F11: =F10/F3 -> 0.21412694
A13: Non-operating items | B13: 14 | C13: -17 | D13: -364 | E13: 70 | F13: 220
A14: Net finance charges | B14: 651 | C14: 919 | D14: 712 | E14: 885 | F14: 771
A15: Share of associate profits | B15: 334 | C15: 417 | D15: 443 | E15: 414 | F15: 193
A16: Profit before tax | B16: =B10-B13-B14+B15 -> 3400 | C16: =C10-C13-C14+C15 -> 3924 | D16: =D10-D13-D14+D15 -> 5642 | E16: =E10-E13-E14+E15 -> 5460 | F16: =F10-F13-F14+F15 -> 3537
A17: Taxation | B17: 907 | C17: 1049 | D17: 1163 | E17: 1294 | F17: 999
A18: Profit for the year | B18: =B16-B17 -> 2493 | C18: =C16-C17 -> 2875 | D18: =D16-D17 -> 4479 | E18: =E16-E17 -> 4166 | F18: =F16-F17 -> 2538
A20: Depreciation & amortisation | B20: 447 | C20: 828 | D20: 1297 | E20: 493 | F20: 1718
A21: Capex | B21: =626+13 -> 639 | C21: =1097+17 -> 1114 | D21: =1417+16 -> 1433 | E21: 1524 | F21: =1612+195 -> 1807
A22: Change in working capital | B22: 331 | C22: -179 | D22: -1414 | E22: -768 | F22: -77

Sheet Projections
A1: DIAGEO PLC - PROJECTIONS ($ millions) | B1: FY25 | C1: FY26 | D1: FY27 | E1: FY28 | F1: FY29 | G1: FY30
A3: Net sales | B3: =Historical!F3 -> 20245 | C3: =B3*(1+C4) -> 20042.55 | D3: =C3*(1+D4) -> 20443.401 | E3: =D3*(1+E4) -> 21261.137 | F3: =E3*(1+F4) -> 22111.583 | G3: =F3*(1+G4) -> 22885.488
A4: Revenue growth % | C4: =Assumptions!B10 -> -0.01 | D4: =Assumptions!B11 -> 0.02 | E4: =Assumptions!B12 -> 0.04 | F4: =Assumptions!B13 -> 0.04 | G4: =Assumptions!B14 -> 0.035
A6: EBIT | C6: =C3*C7 -> 4409.361 | D6: =D3*D7 -> 5110.8502 | E6: =E3*E7 -> 5846.8127 | F6: =F3*F7 -> 6412.3589 | G6: =G3*G7 -> 6751.2189
A7: EBIT margin % | C7: =Assumptions!B18 -> 0.22 | D7: =Assumptions!B19 -> 0.25 | E7: =Assumptions!B20 -> 0.275 | F7: =Assumptions!B21 -> 0.29 | G7: =Assumptions!B22 -> 0.295
A8: Tax on EBIT | C8: =C6*(Assumptions!$B$25) -> 1014.153 | D8: =D6*(Assumptions!$B$25) -> 1175.4956 | E8: =E6*(Assumptions!$B$25) -> 1344.7669 | F8: =F6*(Assumptions!$B$25) -> 1474.8426 | G8: =G6*(Assumptions!$B$25) -> 1552.7804
A9: NOPAT (EBIT × (1-Tax)) | C9: =C6*(1-Assumptions!$B$25) -> 3395.208 | D9: =D6*(1-Assumptions!$B$25) -> 3935.3547 | E9: =E6*(1-Assumptions!$B$25) -> 4502.0458 | F9: =F6*(1-Assumptions!$B$25) -> 4937.5164 | G9: =G6*(1-Assumptions!$B$25) -> 5198.4386
A11: D&A | C11: =C3*(Assumptions!$B$26) -> 901.91475 | D11: =D3*(Assumptions!$B$26) -> 919.95304 | E11: =E3*(Assumptions!$B$26) -> 956.75117 | F11: =F3*(Assumptions!$B$26) -> 995.02121 | G11: =G3*(Assumptions!$B$26) -> 1029.847
A12: Capex | C12: =C3*(Assumptions!$B$27) -> 1402.9785 | D12: =D3*(Assumptions!$B$27) -> 1431.0381 | E12: =E3*(Assumptions!$B$27) -> 1488.2796 | F12: =F3*(Assumptions!$B$27) -> 1547.8108 | G12: =G3*(Assumptions!$B$27) -> 1601.9842
A13: Change in working capital | C13: =C3*(Assumptions!$B$28) -> 200.4255 | D13: =D3*(Assumptions!$B$28) -> 204.43401 | E13: =E3*(Assumptions!$B$28) -> 212.61137 | F13: =F3*(Assumptions!$B$28) -> 221.11583 | G13: =G3*(Assumptions!$B$28) -> 228.85488
A14: Free Cash Flow (FCF) | C14: =C9+C11-C12-C13 -> 2693.7187 | D14: =D9+D11-D12-D13 -> 3219.8357 | E14: =E9+E11-E12-E13 -> 3757.906 | F14: =F9+F11-F12-F13 -> 4163.611 | G14: =G9+G11-G12-G13 -> 4397.4465

Sheet Sensitivity
A1: DIAGEO PLC - SENSITIVITY ANALYSIS
A3: Target Price (£) — WACC vs Terminal Growth Rate
A5: =DCF!B26 -> 19.88612 | B5: 0.0625 | C5: 0.0675 | D5: 0.0726 | E5: 0.0775 | F5: 0.0825
A6: 0.0175 | B6: 22.8 | C6: 20 | D6: 17.6 | E6: 15.7 | F6: 14
A7: 0.02 | B7: 24.2 | C7: 21.1 | D7: 18.5 | E7: 16.4 | F7: 14.6
A8: 0.0225 | B8: 25.8 | C8: 22.3 | D8: 19.89 | E8: 17.2 | F8: 15.3
A9: 0.025 | B9: 27.6 | C9: 23.7 | D9: 20.9 | E9: 18.1 | F9: 16
A10: 0.0275 | B10: 29.7 | C10: 25.3 | D10: 22 | E10: 19 | F10: 16.8
A12: Base case: BUY at £19.89 (19% upside).
A13: Bear case: (WACC 8.25%, g 1.75%) implies £14 — 16% downside limited.
A14: Asymmetric risk/reward supports Buy rating.

Sheet DCF
A1: DIAGEO PLC - DCF VALUATION | B1: Column1 | C1: Column2 | D1: Column3 | E1: Column4 | F1: Column5
B2: FY26 | C2: FY27 | D2: FY28 | E2: FY29 | F2: FY30
A3: FCF ($m) | B3: =Projections!C14 -> 2693.7187 | C3: =Projections!D14 -> 3219.8357 | D3: =Projections!E14 -> 3757.906 | E3: =Projections!F14 -> 4163.611 | F3: =Projections!G14 -> 4397.4465
A4: Year (1, 2, 3, 4, 5) | B4: 1 | C4: 2 | D4: 3 | E4: 4 | F4: 5
A5: Discount factor | B5: =1/(1+Assumptions!$B$43)^B4 -> 0.93232734 | C5: =1/(1+Assumptions!$B$43)^C4 -> 0.86923427 | D5: =1/(1+Assumptions!$B$43)^D4 -> 0.81041087 | E5: =1/(1+Assumptions!$B$43)^E4 -> 0.75556821 | F5: =1/(1+Assumptions!$B$43)^F4 -> 0.7044369
A6: PV of FCF | B6: =B3*B5 -> 2511.4276 | C6: =C3*C5 -> 2798.7915 | D6: =D3*D5 -> 3045.4478 | E6: =E3*E5 -> 3145.8921 | F6: =F3*F5 -> 3097.7236
A8: Sum of PV of FCFs | B8: =SUM(B6:F6) -> 14599.283
A10: TERMINAL VALUE | B10: Column1
A11: FCF FY30 (terminal year) | B11: =F3 -> 4397.4465
A12: Terminal growth rate | B12: =Assumptions!B15 -> 0.0225
A13: WACC | B13: =Assumptions!B43 -> 0.072584659
A14: Terminal value ($m) | B14: =F3*(1+B12*100%)/(Assumptions!B43-DCF!B12*100%) -> 89775.774
A15: PV of Terminal Value | B15: =B14*F5 -> 63241.368
A17: ENTERPRISE VALUE | B17: Column1
A18: Enterprise value ($m) | B18: =B8+B15 -> 77840.65
A19: Less: Net debt ($m) | B19: =Assumptions!B39 -> 21900
A20: Equity value ($m) | B20: =B18-B19 -> 55940.65
A22: PER SHARE | B22: Column1
A23: Shares outstanding (m) | B23: =Assumptions!B47 -> 2215
A24: Equity value per share ($) | B24: =B20/B23 -> 25.255373
A25: FX rate (GBP/USD) | B25: 1.27
A26: Equity value per share (£) | B26: =B24/1.27 -> 19.88612
A27: Current share price (£) | B27: 16.65
A28: Upside / (Downside) % | B28: =(B26-B27)/B27 -> 0.19436157
A29: Recommendation | B29: Buy (upside>15%)

Sheet Comp
A2: DIAGEO - COMPARABLE COMPANIES ANALYSIS
B3: Market Cap ($bn) | C3: EV ($bn) | D3: Revenue ($bn) | E3: EBITDA ($bn) | F3: EV/Revenue | G3: EV/EBITDA | H3: P/E (TTM)
A4: Company
A5: Pernod Ricard | B5: 15.27 | C5: 25.94 | D5: 9.4 | E5: 2.62 | F5: 2.76 | G5: 9.88 | H5: 12.72
A6: Brown-Forman | B6: 12.12 | C6: 14.26 | D6: 3.92 | E6: 1.19 | F6: 3.64 | G6: 13.08 | H6: 16.96
A7: Constellation Brands | B7: 19.91 | C7: 30.34 | D7: 9.21 | E7: 3.43 | F7: 3.37 | G7: 9.29 | H7: 11.2
A8: Median (peers) | F8: 3.37 | G8: 9.88 | H8: 12.72
A10: Diageo | B10: 45.5 | C10: 67.4 | D10: 20.25 | E10: 6.05 | F10: =C10/D10 -> 3.3283951 | G10: =C10/E10 -> 11.140496 | H10: 14.25
A12: Diageo implied value using peer multiples:
A13: Implied EV using peer EV/EBITDA | B13: =E10*G8 -> 59.774
A14: Implied EV using peer EV/Revenue | B14: =D10*F8 -> 68.2425
A15: Less: Net debt ($bn) | B15: =Assumptions!B51/1000 -> 21.9
A16: Implied equity value ($bn) | B16: =B13-B15 -> 37.874
A17: Implied equity value — EV/Revenue method ($bn) | B17: =B14-B15 -> 46.3425
A18: Implied share price ($) | B18: =(Comp!B13-Comp!B15)*1000/Assumptions!B47 -> 17.098871
A19: Implied share price — EV/Revenue method($) | B19: =B17*1000/Assumptions!B47 -> 20.922122
A20: Implied share price (£) | B20: =B18/Assumptions!B49 -> 13.463678
A21: Implied share price (£) — EV/Revenue | B21: =B19/Assumptions!B49 -> 16.474112
A22: Average Comps target (£) | B22: =(B20+B21)/2 -> 14.968895
A24: Comparison summary:
A25: DCF target (£) | B25: =DCF!B26 -> 19.88612
A26: Comps target (£) | B26: =AVERAGE((B20),(B21)) -> 14.968895
A27: Current price (£) | B27: 16.65
A28: Final target (£) — average of DCF and Comps | B28: =(Comp!B25+Comp!B26)/2 -> 17.427508
A29: Upside to final target % | B29: =(B28-B27)/B27 -> 0.046697152
A31: Recommendation | B31: HOLD / BUY on recovery
